export default async function getFailure() {
  throw new Error('error on purpose for test')
}
